Workbook

Sheet Start Here
A1: ACC Nursing Services Toolkit
A2: Built for tracking ACC district nursing billing, approvals, complex cases and declines
A5: Tab | B5: What it's for
A6: Billing Log | B6: Paste your CSV/PMS export here each time. This is the single source of truth — every other sheet reads from it.
A7: Year Summary | B7: Auto-calculated monthly totals: invoiced vs paid, split into Packages (NS01-03) and NS04/NS05/NS06. Updates automatically from Billing Log.
A8: NS04-NS05 Approvals | B8: Manual tracker for Extended Nursing and Ongoing Nursing approvals — the ones that need ACC approval and expire. Salmon-flags anything expiring within a month.
A9: Complex Cases | B9: Free-form log for the 'weird' cases — what's unusual, what was decided, who decided it, and what to follow up on.
A10: Decline Tracker | B10: Tracks decline letters: date received, period/reason declined, who you've notified, and resubmission status.
A12: How the Billing Log works
A13: 1. | B13: Export your billing data from your PMS or the ACC eBusiness portal.
A14: 2. | B14: Paste rows into the Billing Log tab starting at row 2, or append below existing rows.
A15: 3. | B15: Set Status (dropdown): Awaiting Billing, Billed, or Remittance (payment chased/overdue). Awaiting Billing and Remittance rows highlight salmon as a follow-up flag; Billed highlights green.
A16: 4. | B16: Year Summary updates automatically. No formulas to touch.
A18: Note on NS06 | B18: No separate approval tracker for NS06 (Subsequent Injury) — it doesn't need ACC approval, just GP notification before billing. It still flows through Billing Log and the Year Summary like everything else.
A19: Note on Chase List | B19: Not included in this version — you mentioned remittances aren't yet part of your workflow, so this was left out until it's useful. Easy to add back in later.

Sheet NS04-NS05 Approvals
A1: NS04 / NS05 Current Approval Tracker
A2: Manual entry. Only patients on Extended Nursing (NS04) or Ongoing Nursing (NS05) — the services that need ACC approval and expire. Row highlights salmon when expiry is within a month, so you know to follow up.
A4: Patient Name | B4: Patient NHI | C4: Patient DOB | D4: Claim Number | E4: ACC45 Number | F4: Service Code | G4: Approval Start Date | H4: Approval End Date / PO Expiry | I4: Approved Hours/Consults | J4: Days Until Expiry | K4: Status | L4: ACC Emailed Renewal Date | M4: PO Number | N4: Notes
A5: Grace Whaanga | B5: GRW4821 | C5: 21492 | D5: 10051223456 | E5: AB12345 | F5: NS05 | G5: 46037 | H5: 46402 | I5: 6 hours p/month | J5: =IF(H5="","",H5-TODAY()) -> 197 | K5: =IF(H5="","",IF(J5<0,"EXPIRED",IF(J5<=30,"Expiring Soon (<30 days)","Active"))) -> Active | M5: 10004521 | N5: Permanent nursing need, T12 spinal injury - hourly rate ongoing care
A6: Terry Ah Chong | B6: TAC5567 | C6: 28989 | D6: 10052987765 | E6: CD22187 | F6: NS04 | G6: 46183 | H6: 46213 | I6: 30 | J6: =IF(H6="","",H6-TODAY()) -> 8 | K6: =IF(H6="","",IF(J6<0,"EXPIRED",IF(J6<=30,"Expiring Soon (<30 days)","Active"))) -> Expiring Soon (<30 days) | M6: 10005544 | N6: Approval requested early while still on NS03 pkg (was on visit 19 at approval date). Risk period lapses before 26th visit reached - as of 01/07 client on visit 24. Monitor closely.
A7: Priya Naidu | B7: PRN9034 | C7: 23801 | D7: 10048811234 | E7: EF33219 | F7: NS04 | G7: 45992 | H7: 46174 | I7: 25 | J7: =IF(H7="","",H7-TODAY()) -> -31 | K7: =IF(H7="","",IF(J7<0,"EXPIRED",IF(J7<=30,"Expiring Soon (<30 days)","Active"))) -> EXPIRED | L7: 46157 | M7: 10003390 | N7: Further extension requested 20/06/26, initially declined - resubmitted, awaiting ACC response, see Decline Tracker
A8: Wiremu Delamere | B8: WDL6612 | C8: 19246 | D8: 10047765123 | E8: GH44556 | F8: NS05 | G8: 45901 | H8: 46266 | I8: 8 hours p/month | J8: =IF(H8="","",H8-TODAY()) -> 61 | K8: =IF(H8="","",IF(J8<0,"EXPIRED",IF(J8<=30,"Expiring Soon (<30 days)","Active"))) -> Active | M8: 10002210 | N8: Also receiving ACC Home Help support concurrently - overlapping services, consent on file, see Complex Cases
A9: Fa'amatuainu Petelo | B9: FAP7788 | C9: 32497 | D9: 10053322190 | E9: IJ55678 | F9: NS04 | G9: 46113 | H9: 46296 | I9: 20 | J9: =IF(H9="","",H9-TODAY()) -> 91 | K9: =IF(H9="","",IF(J9<0,"EXPIRED",IF(J9<=30,"Expiring Soon (<30 days)","Active"))) -> Active | M9: 10005678 | N9: Straightforward wound care extension, healing well
A10: Chevonne Ngata-Reid | B10: CNR3345 | C10: 34522 | D10: 10049988771 | E10: KL66789 | F10: NS05 | G10: 46054 | H10: 46419 | I10: 3 hours p/month | J10: =IF(H10="","",H10-TODAY()) -> 214 | K10: =IF(H10="","",IF(J10<0,"EXPIRED",IF(J10<=30,"Expiring Soon (<30 days)","Active"))) -> Active | M10: 10004432 | N10: Ongoing care for original injury + new subsequent shoulder injury lodged this month, see Complex Cases
A11: Duc Minh Pham | B11: DMP2211 | C11: 26041 | D11: 10046654321 | E11: MN77890 | F11: NS04 | G11: 46188 | H11: 46218 | I11: 15 | J11: =IF(H11="","",H11-TODAY()) -> 13 | K11: =IF(H11="","",IF(J11<0,"EXPIRED",IF(J11<=30,"Expiring Soon (<30 days)","Active"))) -> Expiring Soon (<30 days) | M11: 10004890 | N11: Consequential sacral pressure injury identified, new ACC45 lodged 18/06/26, see Complex Cases
A12: Ashleigh Broughton | B12: ASB8890 | C12: 36185 | D12: 10054411002 | E12: OP88901 | F12: NS04 | G12: 46162 | H12: 46346 | I12: 25 | J12: =IF(H12="","",H12-TODAY()) -> 141 | K12: =IF(H12="","",IF(J12<0,"EXPIRED",IF(J12<=30,"Expiring Soon (<30 days)","Active"))) -> Active | N12: Transferred from previous supplier 20/05/26 mid-package - PO not yet issued, invoicing on hold, see Complex Cases
A13: Rongomai Tapsell | B13: RGT1123 | C13: 17987 | D13: 10041122334 | E13: QR99012 | F13: NS05 | G13: 45667 | H13: 46032 | I13: 4 hours p/month | J13: =IF(H13="","",H13-TODAY()) -> -173 | K13: =IF(H13="","",IF(J13<0,"EXPIRED",IF(J13<=30,"Expiring Soon (<30 days)","Active"))) -> EXPIRED | M13: 10001005 | N13: Renewal declined - hours reduction disputed, see Decline Tracker
A14: Sela Fifita | B14: SLF4456 | C14: 30600 | D14: 10050099887 | E14: ST00123 | F14: NS04 | G14: 46082 | H14: 46266 | I14: 18 | J14: =IF(H14="","",H14-TODAY()) -> 61 | K14: =IF(H14="","",IF(J14<0,"EXPIRED",IF(J14<=30,"Expiring Soon (<30 days)","Active"))) -> Active | M14: 10005121 | N14: NS06 subsequent injury treatments also declined over 50-treatment cap, see Decline Tracker
J15: =IF(H15="","",H15-TODAY()) | K15: =IF(H15="","",IF(J15<0,"EXPIRED",IF(J15<=30,"Expiring Soon (<30 days)","Active")))
J16: =IF(H16="","",H16-TODAY()) | K16: =IF(H16="","",IF(J16<0,"EXPIRED",IF(J16<=30,"Expiring Soon (<30 days)","Active")))
J17: =IF(H17="","",H17-TODAY()) | K17: =IF(H17="","",IF(J17<0,"EXPIRED",IF(J17<=30,"Expiring Soon (<30 days)","Active")))
J18: =IF(H18="","",H18-TODAY()) | K18: =IF(H18="","",IF(J18<0,"EXPIRED",IF(J18<=30,"Expiring Soon (<30 days)","Active")))
J19: =IF(H19="","",H19-TODAY()) | K19: =IF(H19="","",IF(J19<0,"EXPIRED",IF(J19<=30,"Expiring Soon (<30 days)","Active")))
J20: =IF(H20="","",H20-TODAY()) | K20: =IF(H20="","",IF(J20<0,"EXPIRED",IF(J20<=30,"Expiring Soon (<30 days)","Active")))
J21: =IF(H21="","",H21-TODAY()) | K21: =IF(H21="","",IF(J21<0,"EXPIRED",IF(J21<=30,"Expiring Soon (<30 days)","Active")))
J22: =IF(H22="","",H22-TODAY()) | K22: =IF(H22="","",IF(J22<0,"EXPIRED",IF(J22<=30,"Expiring Soon (<30 days)","Active")))
J23: =IF(H23="","",H23-TODAY()) | K23: =IF(H23="","",IF(J23<0,"EXPIRED",IF(J23<=30,"Expiring Soon (<30 days)","Active")))
J24: =IF(H24="","",H24-TODAY()) | K24: =IF(H24="","",IF(J24<0,"EXPIRED",IF(J24<=30,"Expiring Soon (<30 days)","Active")))
J25: =IF(H25="","",H25-TODAY()) | K25: =IF(H25="","",IF(J25<0,"EXPIRED",IF(J25<=30,"Expiring Soon (<30 days)","Active")))
J26: =IF(H26="","",H26-TODAY()) | K26: =IF(H26="","",IF(J26<0,"EXPIRED",IF(J26<=30,"Expiring Soon (<30 days)","Active")))
... J100: =IF(H100="","",H100-TODAY()) | K100: =IF(H100="","",IF(J100<0,"EXPIRED",IF(J100<=30,"Expiring Soon (<30 days)","Active")))
A103: Status: auto-calculated label — 'Active' (more than 30 days left), 'Expiring Soon' (within 30 days, also triggers the salmon row highlight), or 'EXPIRED' (past the end date and not yet renewed).

Sheet Billing Log
A1: Patient Name | B1: Patient NHI | C1: Claim Number | D1: Purchase Order Number | E1: ACC45 Number | F1: Service Code | G1: Invoice Sheet | H1: Invoice Date | I1: Amount Invoiced | J1: Date Paid | K1: Amount Paid | L1: Status | M1: Notes | N1: Invoice Sheet = the name/label of your invoicing report, e.g. EXTMAR26 for Extension March 2026 invoicing. Invoice Date = the actual date you billed it, used by Year Summary to bucket totals by month.
A2: Grace Whaanga | B2: GRW4821 | C2: 10051223456 | D2: 10004521 | E2: AB12345 | F2: NS05 | G2: ONGOINGJAN26 | H2: 46053 | I2: 288 | J2: 46067 | K2: 288 | L2: Billed
A3: Grace Whaanga | B3: GRW4821 | C3: 10051223456 | D3: 10004521 | E3: AB12345 | F3: NS05 | G3: ONGOINGFEB26 | H3: 46081 | I3: 288 | J3: 46095 | K3: 288 | L3: Billed
A4: Grace Whaanga | B4: GRW4821 | C4: 10051223456 | D4: 10004521 | E4: AB12345 | F4: NS05 | G4: ONGOINGMAR26 | H4: 46112 | I4: 288 | J4: 46126 | K4: 288 | L4: Billed
A5: Grace Whaanga | B5: GRW4821 | C5: 10051223456 | D5: 10004521 | E5: AB12345 | F5: NS05 | G5: ONGOINGAPR26 | H5: 46142 | I5: 288 | J5: 46156 | K5: 288 | L5: Billed
A6: Grace Whaanga | B6: GRW4821 | C6: 10051223456 | D6: 10004521 | E6: AB12345 | F6: NS05 | G6: ONGOINGMAY26 | H6: 46173 | I6: 288 | J6: 46187 | K6: 288 | L6: Billed
A7: Grace Whaanga | B7: GRW4821 | C7: 10051223456 | D7: 10004521 | E7: AB12345 | F7: NS05 | G7: ONGOINGJUN26 | H7: 46203 | I7: 288 | J7: 46217 | K7: 288 | L7: Billed
A8: Terry Ah Chong | B8: TAC5567 | C8: 10052987765 | D8: 10005544 | E8: CD22187 | F8: NS03 | G8: PKGJUN26 | H8: 46182 | I8: 1850 | J8: 46196 | K8: 1850 | L8: Billed | M8: NS03 Long Term package - covers visits 1-25
A9: Terry Ah Chong | B9: TAC5567 | C9: 10052987765 | D9: 10005544 | E9: CD22187 | F9: NS04 | G9: EXTJUN26 | H9: 46201 | I9: 95 | L9: Awaiting Billing | M9: First Extended Nursing consult - visit 26
A10: Terry Ah Chong | B10: TAC5567 | C10: 10052987765 | D10: 10005544 | E10: CD22187 | F10: NS04 | G10: EXTJUL26 | H10: 46204 | I10: 95 | L10: Awaiting Billing | M10: Visit 27
A11: Priya Naidu | B11: PRN9034 | C11: 10048811234 | D11: 10003390 | E11: EF33219 | F11: NS04 | G11: EXTJAN26 | H11: 46032 | I11: 95 | J11: 46046 | K11: 95 | L11: Billed
A12: Priya Naidu | B12: PRN9034 | C12: 10048811234 | D12: 10003390 | E12: EF33219 | F12: NS04 | G12: EXTFEB26 | H12: 46060 | I12: 95 | J12: 46074 | K12: 95 | L12: Billed
A13: Priya Naidu | B13: PRN9034 | C13: 10048811234 | D13: 10003390 | E13: EF33219 | F13: NS04 | G13: EXTMAR26 | H13: 46087 | I13: 95 | J13: 46101 | K13: 95 | L13: Billed
A14: Priya Naidu | B14: PRN9034 | C14: 10048811234 | D14: 10003390 | E14: EF33219 | F14: NS04 | G14: EXTAPR26 | H14: 46115 | I14: 95 | L14: Remittance | M14: Payment overdue - claim under review pending extension decision
A15: Priya Naidu | B15: PRN9034 | C15: 10048811234 | D15: 10003390 | E15: EF33219 | F15: NS04 | G15: EXTMAY26 | H15: 46143 | I15: 95 | L15: Remittance | M15: Payment overdue - claim under review pending extension decision
A16: Wiremu Delamere | B16: WDL6612 | C16: 10047765123 | D16: 10002210 | E16: GH44556 | F16: NS05 | G16: ONGOINGJAN26 | H16: 46053 | I16: 384 | J16: 46063 | K16: 384 | L16: Billed
A17: Wiremu Delamere | B17: WDL6612 | C17: 10047765123 | D17: 10002210 | E17: GH44556 | F17: NS05 | G17: ONGOINGFEB26 | H17: 46081 | I17: 384 | J17: 46091 | K17: 384 | L17: Billed
A18: Wiremu Delamere | B18: WDL6612 | C18: 10047765123 | D18: 10002210 | E18: GH44556 | F18: NS05 | G18: ONGOINGMAR26 | H18: 46112 | I18: 384 | J18: 46122 | K18: 384 | L18: Billed
A19: Wiremu Delamere | B19: WDL6612 | C19: 10047765123 | D19: 10002210 | E19: GH44556 | F19: NS05 | G19: ONGOINGAPR26 | H19: 46142 | I19: 384 | J19: 46152 | K19: 384 | L19: Billed
A20: Wiremu Delamere | B20: WDL6612 | C20: 10047765123 | D20: 10002210 | E20: GH44556 | F20: NS05 | G20: ONGOINGMAY26 | H20: 46173 | I20: 384 | J20: 46183 | K20: 384 | L20: Billed
A21: Wiremu Delamere | B21: WDL6612 | C21: 10047765123 | D21: 10002210 | E21: GH44556 | F21: NS05 | G21: ONGOINGJUN26 | H21: 46203 | I21: 384 | J21: 46213 | K21: 384 | L21: Billed
A22: Fa'amatuainu Petelo | B22: FAP7788 | C22: 10053322190 | D22: 10005678 | E22: IJ55678 | F22: NS04 | G22: EXTAPR26 | H22: 46115 | I22: 95 | J22: 46130 | K22: 95 | L22: Billed
A23: Fa'amatuainu Petelo | B23: FAP7788 | C23: 10053322190 | D23: 10005678 | E23: IJ55678 | F23: NS04 | G23: EXTAPR26 | H23: 46122 | I23: 95 | J23: 46137 | K23: 95 | L23: Billed
A24: Fa'amatuainu Petelo | B24: FAP7788 | C24: 10053322190 | D24: 10005678 | E24: IJ55678 | F24: NS04 | G24: EXTAPR26 | H24: 46129 | I24: 95 | J24: 46144 | K24: 95 | L24: Billed
A25: Fa'amatuainu Petelo | B25: FAP7788 | C25: 10053322190 | D25: 10005678 | E25: IJ55678 | F25: NS04 | G25: EXTAPR26 | H25: 46136 | I25: 95 | J25: 46151 | K25: 95 | L25: Billed
A26: Fa'amatuainu Petelo | B26: FAP7788 | C26: 10053322190 | D26: 10005678 | E26: IJ55678 | F26: NS04 | G26: EXTMAY26 | H26: 46143 | I26: 95 | J26: 46158 | K26: 95 | L26: Billed
A27: Fa'amatuainu Petelo | B27: FAP7788 | C27: 10053322190 | D27: 10005678 | E27: IJ55678 | F27: NS04 | G27: EXTMAY26 | H27: 46150 | I27: 95 | J27: 46165 | K27: 95 | L27: Billed
... A31: Chevonne Ngata-Reid | B31: CNR3345 | C31: 10049988771 | D31: 10004432 | E31: KL66789 | F31: NS05 | G31: ONGOINGMAY26 | H31: 46173 | I31: 144 | J31: 46185 | K31: 144 | L31: Billed
A32: Chevonne Ngata-Reid | B32: CNR3345 | C32: 10049988771 | D32: 10004432 | E32: KL66789 | F32: NS06 | G32: SUBJUN26 | H32: 46199 | I32: 85 | L32: Awaiting Billing | M32: First treatment for new shoulder subsequent injury - GP notified, no approval required
A33: Duc Minh Pham | B33: DMP2211 | C33: 10046654321 | D33: 10004890 | E33: MN77890 | F33: NS03 | G33: PKGMAY26 | H33: 46162 | I33: 1850 | J33: 46176 | K33: 1850 | L33: Billed | M33: NS03 package for original hip fracture
A34: Duc Minh Pham | B34: DMP2211 | C34: 10046654321 | D34: 10004890 | E34: MN77890 | F34: NS04 | G34: EXTJUN26 | H34: 46193 | I34: 95 | J34: 46205 | K34: 95 | L34: Billed | M34: Extended Nursing incl. consequential pressure injury wound care
A35: Duc Minh Pham | B35: DMP2211 | C35: 10046654321 | D35: 10004890 | E35: MN77890 | F35: NS04 | G35: EXTJUN26B | H35: 46200 | I35: 95 | L35: Awaiting Billing
A36: Rongomai Tapsell | B36: RGT1123 | C36: 10041122334 | D36: 10001005 | E36: QR99012 | F36: NS05 | G36: ONGOINGOCT25 | H36: 45961 | I36: 192 | J36: 45981 | K36: 192 | L36: Billed
A37: Rongomai Tapsell | B37: RGT1123 | C37: 10041122334 | D37: 10001005 | E37: QR99012 | F37: NS05 | G37: ONGOINGNOV25 | H37: 45991 | I37: 192 | J37: 46011 | K37: 192 | L37: Billed
A38: Rongomai Tapsell | B38: RGT1123 | C38: 10041122334 | D38: 10001005 | E38: QR99012 | F38: NS05 | G38: ONGOINGDEC25 | H38: 46022 | I38: 192 | J38: 46042 | K38: 192 | L38: Billed
A39: Sela Fifita | B39: SLF4456 | C39: 10050099887 | D39: 10005121 | E39: ST00123 | F39: NS04 | G39: EXTMAR26 | H39: 46086 | I39: 95 | J39: 46100 | K39: 95 | L39: Billed
A40: Sela Fifita | B40: SLF4456 | C40: 10050099887 | D40: 10005121 | E40: ST00123 | F40: NS04 | G40: EXTMAR26 | H40: 46100 | I40: 95 | J40: 46114 | K40: 95 | L40: Billed
A41: Sela Fifita | B41: SLF4456 | C41: 10050099887 | D41: 10005121 | E41: ST00123 | F41: NS04 | G41: EXTAPR26 | H41: 46114 | I41: 95 | J41: 46128 | K41: 95 | L41: Billed
A42: Sela Fifita | B42: SLF4456 | C42: 10050099887 | D42: 10005121 | E42: ST00123 | F42: NS04 | G42: EXTAPR26 | H42: 46128 | I42: 95 | J42: 46142 | K42: 95 | L42: Billed
A43: Sela Fifita | B43: SLF4456 | C43: 10050099887 | D43: 10005121 | E43: ST00123 | F43: NS06 | G43: SUBJAN26 | H43: 46030 | I43: 85 | J43: 46044 | K43: 85 | L43: Billed | M43: Treatment count approaching 50-cap - see Decline Tracker
...

Sheet Year Summary
A1: Year Summary
A2: Auto-calculated from Billing Log — invoiced and paid totals by month, split by service group
A4: Month | B4: Packages (NS01-03) | D4: NS04 | F4: NS05 | H4: NS06
B5: Invoiced | C5: Paid | D5: Invoiced | E5: Paid | F5: Invoiced | G5: Paid | H5: Invoiced | I5: Paid
A6: Jan | B6: =SUMPRODUCT(('Billing Log'!$H$2:$H$501<>"")*(MONTH('Billing Log'!$H$2:$H$501)=1)*(('Billing Log'!$F$2:$F$501="NS01")+('Billing Log'!$F$2:$F$501="NS02")+('Billing Log'!$F$2:$F$501="NS03"))*'Billing Log'!$I$2:$I$501) -> 0 | C6: =SUMPRODUCT(('Billing Log'!$J$2:$J$501<>"")*(MONTH('Billing Log'!$J$2:$J$501)=1)*(('Billing Log'!$F$2:$F$501="NS01")+('Billing Log'!$F$2:$F$501="NS02")+('Billing Log'!$F$2:$F$501="NS03"))*'Billing Log'!$K$2:$K$501) -> 0 | D6: =SUMPRODUCT(('Billing Log'!$H$2:$H$501<>"")*(MONTH('Billing Log'!$H$2:$H$501)=1)*('Billing Log'!$F$2:$F$501="NS04")*'Billing Log'!$I$2:$I$501) -> 95 | E6: =SUMPRODUCT(('Billing Log'!$J$2:$J$501<>"")*(MONTH('Billing Log'!$J$2:$J$501)=1)*('Billing Log'!$F$2:$F$501="NS04")*'Billing Log'!$K$2:$K$501) -> 95 | F6: =SUMPRODUCT(('Billing Log'!$H$2:$H$501<>"")*(MONTH('Billing Log'!$H$2:$H$501)=1)*('Billing Log'!$F$2:$F$501="NS05")*'Billing Log'!$I$2:$I$501) -> 672 | G6: =SUMPRODUCT(('Billing Log'!$J$2:$J$501<>"")*(MONTH('Billing Log'!$J$2:$J$501)=1)*('Billing Log'!$F$2:$F$501="NS05")*'Billing Log'!$K$2:$K$501) -> 192 | H6: =SUMPRODUCT(('Billing Log'!$H$2:$H$501<>"")*(MONTH('Billing Log'!$H$2:$H$501)=1)*('Billing Log'!$F$2:$F$501="NS06")*'Billing Log'!$I$2:$I$501) -> 170 | I6: =SUMPRODUCT(('Billing Log'!$J$2:$J$501<>"")*(MONTH('Billing Log'!$J$2:$J$501)=1)*('Billing Log'!$F$2:$F$501="NS06")*'Billing Log'!$K$2:$K$501) -> 85
A7: Feb | B7: =SUMPRODUCT(('Billing Log'!$H$2:$H$501<>"")*(MONTH('Billing Log'!$H$2:$H$501)=2)*(('Billing Log'!$F$2:$F$501="NS01")+('Billing Log'!$F$2:$F$501="NS02")+('Billing Log'!$F$2:$F$501="NS03"))*'Billing Log'!$I$2:$I$501) -> 0 | C7: =SUMPRODUCT(('Billing Log'!$J$2:$J$501<>"")*(MONTH('Billing Log'!$J$2:$J$501)=2)*(('Billing Log'!$F$2:$F$501="NS01")+('Billing Log'!$F$2:$F$501="NS02")+('Billing Log'!$F$2:$F$501="NS03"))*'Billing Log'!$K$2:$K$501) -> 0 | D7: =SUMPRODUCT(('Billing Log'!$H$2:$H$501<>"")*(MONTH('Billing Log'!$H$2:$H$501)=2)*('Billing Log'!$F$2:$F$501="NS04")*'Billing Log'!$I$2:$I$501) -> 95 | E7: =SUMPRODUCT(('Billing Log'!$J$2:$J$501<>"")*(MONTH('Billing Log'!$J$2:$J$501)=2)*('Billing Log'!$F$2:$F$501="NS04")*'Billing Log'!$K$2:$K$501) -> 95 | F7: =SUMPRODUCT(('Billing Log'!$H$2:$H$501<>"")*(MONTH('Billing Log'!$H$2:$H$501)=2)*('Billing Log'!$F$2:$F$501="NS05")*'Billing Log'!$I$2:$I$501) -> 816 | G7: =SUMPRODUCT(('Billing Log'!$J$2:$J$501<>"")*(MONTH('Billing Log'!$J$2:$J$501)=2)*('Billing Log'!$F$2:$F$501="NS05")*'Billing Log'!$K$2:$K$501) -> 672 | H7: =SUMPRODUCT(('Billing Log'!$H$2:$H$501<>"")*(MONTH('Billing Log'!$H$2:$H$501)=2)*('Billing Log'!$F$2:$F$501="NS06")*'Billing Log'!$I$2:$I$501) -> 170 | I7: =SUMPRODUCT(('Billing Log'!$J$2:$J$501<>"")*(MONTH('Billing Log'!$J$2:$J$501)=2)*('Billing Log'!$F$2:$F$501="NS06")*'Billing Log'!$K$2:$K$501) -> 170
A8: Mar | B8: =SUMPRODUCT(('Billing Log'!$H$2:$H$501<>"")*(MONTH('Billing Log'!$H$2:$H$501)=3)*(('Billing Log'!$F$2:$F$501="NS01")+('Billing Log'!$F$2:$F$501="NS02")+('Billing Log'!$F$2:$F$501="NS03"))*'Billing Log'!$I$2:$I$501) -> 0 | C8: =SUMPRODUCT(('Billing Log'!$J$2:$J$501<>"")*(MONTH('Billing Log'!$J$2:$J$501)=3)*(('Billing Log'!$F$2:$F$501="NS01")+('Billing Log'!$F$2:$F$501="NS02")+('Billing Log'!$F$2:$F$501="NS03"))*'Billing Log'!$K$2:$K$501) -> 0 | D8: =SUMPRODUCT(('Billing Log'!$H$2:$H$501<>"")*(MONTH('Billing Log'!$H$2:$H$501)=3)*('Billing Log'!$F$2:$F$501="NS04")*'Billing Log'!$I$2:$I$501) -> 285 | E8: =SUMPRODUCT(('Billing Log'!$J$2:$J$501<>"")*(MONTH('Billing Log'!$J$2:$J$501)=3)*('Billing Log'!$F$2:$F$501="NS04")*'Billing Log'!$K$2:$K$501) -> 190 | F8: =SUMPRODUCT(('Billing Log'!$H$2:$H$501<>"")*(MONTH('Billing Log'!$H$2:$H$501)=3)*('Billing Log'!$F$2:$F$501="NS05")*'Billing Log'!$I$2:$I$501) -> 816 | G8: =SUMPRODUCT(('Billing Log'!$J$2:$J$501<>"")*(MONTH('Billing Log'!$J$2:$J$501)=3)*('Billing Log'!$F$2:$F$501="NS05")*'Billing Log'!$K$2:$K$501) -> 816 | H8: =SUMPRODUCT(('Billing Log'!$H$2:$H$501<>"")*(MONTH('Billing Log'!$H$2:$H$501)=3)*('Billing Log'!$F$2:$F$501="NS06")*'Billing Log'!$I$2:$I$501) -> 170 | I8: =SUMPRODUCT(('Billing Log'!$J$2:$J$501<>"")*(MONTH('Billing Log'!$J$2:$J$501)=3)*('Billing Log'!$F$2:$F$501="NS06")*'Billing Log'!$K$2:$K$501) -> 170
A9: Apr | B9: =SUMPRODUCT(('Billing Log'!$H$2:$H$501<>"")*(MONTH('Billing Log'!$H$2:$H$501)=4)*(('Billing Log'!$F$2:$F$501="NS01")+('Billing Log'!$F$2:$F$501="NS02")+('Billing Log'!$F$2:$F$501="NS03"))*'Billing Log'!$I$2:$I$501) -> 0 | C9: =SUMPRODUCT(('Billing Log'!$J$2:$J$501<>"")*(MONTH('Billing Log'!$J$2:$J$501)=4)*(('Billing Log'!$F$2:$F$501="NS01")+('Billing Log'!$F$2:$F$501="NS02")+('Billing Log'!$F$2:$F$501="NS03"))*'Billing Log'!$K$2:$K$501) -> 0 | D9: =SUMPRODUCT(('Billing Log'!$H$2:$H$501<>"")*(MONTH('Billing Log'!$H$2:$H$501)=4)*('Billing Log'!$F$2:$F$501="NS04")*'Billing Log'!$I$2:$I$501) -> 665 | E9: =SUMPRODUCT(('Billing Log'!$J$2:$J$501<>"")*(MONTH('Billing Log'!$J$2:$J$501)=4)*('Billing Log'!$F$2:$F$501="NS04")*'Billing Log'!$K$2:$K$501) -> 475 | F9: =SUMPRODUCT(('Billing Log'!$H$2:$H$501<>"")*(MONTH('Billing Log'!$H$2:$H$501)=4)*('Billing Log'!$F$2:$F$501="NS05")*'Billing Log'!$I$2:$I$501) -> 816 | G9: =SUMPRODUCT(('Billing Log'!$J$2:$J$501<>"")*(MONTH('Billing Log'!$J$2:$J$501)=4)*('Billing Log'!$F$2:$F$501="NS05")*'Billing Log'!$K$2:$K$501) -> 816 | H9: =SUMPRODUCT(('Billing Log'!$H$2:$H$501<>"")*(MONTH('Billing Log'!$H$2:$H$501)=4)*('Billing Log'!$F$2:$F$501="NS06")*'Billing Log'!$I$2:$I$501) -> 255 | I9: =SUMPRODUCT(('Billing Log'!$J$2:$J$501<>"")*(MONTH('Billing Log'!$J$2:$J$501)=4)*('Billing Log'!$F$2:$F$501="NS06")*'Billing Log'!$K$2:$K$501) -> 255
A10: May | B10: =SUMPRODUCT(('Billing Log'!$H$2:$H$501<>"")*(MONTH('Billing Log'!$H$2:$H$501)=5)*(('Billing Log'!$F$2:$F$501="NS01")+('Billing Log'!$F$2:$F$501="NS02")+('Billing Log'!$F$2:$F$501="NS03"))*'Billing Log'!$I$2:$I$501) -> 1850 | C10: =SUMPRODUCT(('Billing Log'!$J$2:$J$501<>"")*(MONTH('Billing Log'!$J$2:$J$501)=5)*(('Billing Log'!$F$2:$F$501="NS01")+('Billing Log'!$F$2:$F$501="NS02")+('Billing Log'!$F$2:$F$501="NS03"))*'Billing Log'!$K$2:$K$501) -> 0 | D10: =SUMPRODUCT(('Billing Log'!$H$2:$H$501<>"")*(MONTH('Billing Log'!$H$2:$H$501)=5)*('Billing Log'!$F$2:$F$501="NS04")*'Billing Log'!$I$2:$I$501) -> 285 | E10: =SUMPRODUCT(('Billing Log'!$J$2:$J$501<>"")*(MONTH('Billing Log'!$J$2:$J$501)=5)*('Billing Log'!$F$2:$F$501="NS04")*'Billing Log'!$K$2:$K$501) -> 380 | F10: =SUMPRODUCT(('Billing Log'!$H$2:$H$501<>"")*(MONTH('Billing Log'!$H$2:$H$501)=5)*('Billing Log'!$F$2:$F$501="NS05")*'Billing Log'!$I$2:$I$501) -> 816 | G10: =SUMPRODUCT(('Billing Log'!$J$2:$J$501<>"")*(MONTH('Billing Log'!$J$2:$J$501)=5)*('Billing Log'!$F$2:$F$501="NS05")*'Billing Log'!$K$2:$K$501) -> 816 | H10: =SUMPRODUCT(('Billing Log'!$H$2:$H$501<>"")*(MONTH('Billing Log'!$H$2:$H$501)=5)*('Billing Log'!$F$2:$F$501="NS06")*'Billing Log'!$I$2:$I$501) -> 85 | I10: =SUMPRODUCT(('Billing Log'!$J$2:$J$501<>"")*(MONTH('Billing Log'!$J$2:$J$501)=5)*('Billing Log'!$F$2:$F$501="NS06")*'Billing Log'!$K$2:$K$501) -> 170
A11: Jun | B11: =SUMPRODUCT(('Billing Log'!$H$2:$H$501<>"")*(MONTH('Billing Log'!$H$2:$H$501)=6)*(('Billing Log'!$F$2:$F$501="NS01")+('Billing Log'!$F$2:$F$501="NS02")+('Billing Log'!$F$2:$F$501="NS03"))*'Billing Log'!$I$2:$I$501) -> 3700 | C11: =SUMPRODUCT(('Billing Log'!$J$2:$J$501<>"")*(MONTH('Billing Log'!$J$2:$J$501)=6)*(('Billing Log'!$F$2:$F$501="NS01")+('Billing Log'!$F$2:$F$501="NS02")+('Billing Log'!$F$2:$F$501="NS03"))*'Billing Log'!$K$2:$K$501) -> 4350 | D11: =SUMPRODUCT(('Billing Log'!$H$2:$H$501<>"")*(MONTH('Billing Log'!$H$2:$H$501)=6)*('Billing Log'!$F$2:$F$501="NS04")*'Billing Log'!$I$2:$I$501) -> 285 | E11: =SUMPRODUCT(('Billing Log'!$J$2:$J$501<>"")*(MONTH('Billing Log'!$J$2:$J$501)=6)*('Billing Log'!$F$2:$F$501="NS04")*'Billing Log'!$K$2:$K$501) -> 0 | F11: =SUMPRODUCT(('Billing Log'!$H$2:$H$501<>"")*(MONTH('Billing Log'!$H$2:$H$501)=6)*('Billing Log'!$F$2:$F$501="NS05")*'Billing Log'!$I$2:$I$501) -> 672 | G11: =SUMPRODUCT(('Billing Log'!$J$2:$J$501<>"")*(MONTH('Billing Log'!$J$2:$J$501)=6)*('Billing Log'!$F$2:$F$501="NS05")*'Billing Log'!$K$2:$K$501) -> 816 | H11: =SUMPRODUCT(('Billing Log'!$H$2:$H$501<>"")*(MONTH('Billing Log'!$H$2:$H$501)=6)*('Billing Log'!$F$2:$F$501="NS06")*'Billing Log'!$I$2:$I$501) -> 85 | I11: =SUMPRODUCT(('Billing Log'!$J$2:$J$501<>"")*(MONTH('Billing Log'!$J$2:$J$501)=6)*('Billing Log'!$F$2:$F$501="NS06")*'Billing Log'!$K$2:$K$501) -> 0
A12: Jul | B12: =SUMPRODUCT(('Billing Log'!$H$2:$H$501<>"")*(MONTH('Billing Log'!$H$2:$H$501)=7)*(('Billing Log'!$F$2:$F$501="NS01")+('Billing Log'!$F$2:$F$501="NS02")+('Billing Log'!$F$2:$F$501="NS03"))*'Billing Log'!$I$2:$I$501) -> 0 | C12: =SUMPRODUCT(('Billing Log'!$J$2:$J$501<>"")*(MONTH('Billing Log'!$J$2:$J$501)=7)*(('Billing Log'!$F$2:$F$501="NS01")+('Billing Log'!$F$2:$F$501="NS02")+('Billing Log'!$F$2:$F$501="NS03"))*'Billing Log'!$K$2:$K$501) -> 0 | D12: =SUMPRODUCT(('Billing Log'!$H$2:$H$501<>"")*(MONTH('Billing Log'!$H$2:$H$501)=7)*('Billing Log'!$F$2:$F$501="NS04")*'Billing Log'!$I$2:$I$501) -> 95 | E12: =SUMPRODUCT(('Billing Log'!$J$2:$J$501<>"")*(MONTH('Billing Log'!$J$2:$J$501)=7)*('Billing Log'!$F$2:$F$501="NS04")*'Billing Log'!$K$2:$K$501) -> 95 | F12: =SUMPRODUCT(('Billing Log'!$H$2:$H$501<>"")*(MONTH('Billing Log'!$H$2:$H$501)=7)*('Billing Log'!$F$2:$F$501="NS05")*'Billing Log'!$I$2:$I$501) -> 0 | G12: =SUMPRODUCT(('Billing Log'!$J$2:$J$501<>"")*(MONTH('Billing Log'!$J$2:$J$501)=7)*('Billing Log'!$F$2:$F$501="NS05")*'Billing Log'!$K$2:$K$501) -> 672 | H12: =SUMPRODUCT(('Billing Log'!$H$2:$H$501<>"")*(MONTH('Billing Log'!$H$2:$H$501)=7)*('Billing Log'!$F$2:$F$501="NS06")*'Billing Log'!$I$2:$I$501) -> 0 | I12: =SUMPRODUCT(('Billing Log'!$J$2:$J$501<>"")*(MONTH('Billing Log'!$J$2:$J$501)=7)*('Billing Log'!$F$2:$F$501="NS06")*'Billing Log'!$K$2:$K$501) -> 0
A13: Aug | B13: =SUMPRODUCT(('Billing Log'!$H$2:$H$501<>"")*(MONTH('Billing Log'!$H$2:$H$501)=8)*(('Billing Log'!$F$2:$F$501="NS01")+('Billing Log'!$F$2:$F$501="NS02")+('Billing Log'!$F$2:$F$501="NS03"))*'Billing Log'!$I$2:$I$501) -> 0 | C13: =SUMPRODUCT(('Billing Log'!$J$2:$J$501<>"")*(MONTH('Billing Log'!$J$2:$J$501)=8)*(('Billing Log'!$F$2:$F$501="NS01")+('Billing Log'!$F$2:$F$501="NS02")+('Billing Log'!$F$2:$F$501="NS03"))*'Billing Log'!$K$2:$K$501) -> 0 | D13: =SUMPRODUCT(('Billing Log'!$H$2:$H$501<>"")*(MONTH('Billing Log'!$H$2:$H$501)=8)*('Billing Log'!$F$2:$F$501="NS04")*'Billing Log'!$I$2:$I$501) -> 0 | E13: =SUMPRODUCT(('Billing Log'!$J$2:$J$501<>"")*(MONTH('Billing Log'!$J$2:$J$501)=8)*('Billing Log'!$F$2:$F$501="NS04")*'Billing Log'!$K$2:$K$501) -> 0 | F13: =SUMPRODUCT(('Billing Log'!$H$2:$H$501<>"")*(MONTH('Billing Log'!$H$2:$H$501)=8)*('Billing Log'!$F$2:$F$501="NS05")*'Billing Log'!$I$2:$I$501) -> 0 | G13: =SUMPRODUCT(('Billing Log'!$J$2:$J$501<>"")*(MONTH('Billing Log'!$J$2:$J$501)=8)*('Billing Log'!$F$2:$F$501="NS05")*'Billing Log'!$K$2:$K$501) -> 0 | H13: =SUMPRODUCT(('Billing Log'!$H$2:$H$501<>"")*(MONTH('Billing Log'!$H$2:$H$501)=8)*('Billing Log'!$F$2:$F$501="NS06")*'Billing Log'!$I$2:$I$501) -> 0 | I13: =SUMPRODUCT(('Billing Log'!$J$2:$J$501<>"")*(MONTH('Billing Log'!$J$2:$J$501)=8)*('Billing Log'!$F$2:$F$501="NS06")*'Billing Log'!$K$2:$K$501) -> 0
A14: Sep | B14: =SUMPRODUCT(('Billing Log'!$H$2:$H$501<>"")*(MONTH('Billing Log'!$H$2:$H$501)=9)*(('Billing Log'!$F$2:$F$501="NS01")+('Billing Log'!$F$2:$F$501="NS02")+('Billing Log'!$F$2:$F$501="NS03"))*'Billing Log'!$I$2:$I$501) -> 0 | C14: =SUMPRODUCT(('Billing Log'!$J$2:$J$501<>"")*(MONTH('Billing Log'!$J$2:$J$501)=9)*(('Billing Log'!$F$2:$F$501="NS01")+('Billing Log'!$F$2:$F$501="NS02")+('Billing Log'!$F$2:$F$501="NS03"))*'Billing Log'!$K$2:$K$501) -> 0 | D14: =SUMPRODUCT(('Billing Log'!$H$2:$H$501<>"")*(MONTH('Billing Log'!$H$2:$H$501)=9)*('Billing Log'!$F$2:$F$501="NS04")*'Billing Log'!$I$2:$I$501) -> 0 | E14: =SUMPRODUCT(('Billing Log'!$J$2:$J$501<>"")*(MONTH('Billing Log'!$J$2:$J$501)=9)*('Billing Log'!$F$2:$F$501="NS04")*'Billing Log'!$K$2:$K$501) -> 0 | F14: =SUMPRODUCT(('Billing Log'!$H$2:$H$501<>"")*(MONTH('Billing Log'!$H$2:$H$501)=9)*('Billing Log'!$F$2:$F$501="NS05")*'Billing Log'!$I$2:$I$501) -> 0 | G14: =SUMPRODUCT(('Billing Log'!$J$2:$J$501<>"")*(MONTH('Billing Log'!$J$2:$J$501)=9)*('Billing Log'!$F$2:$F$501="NS05")*'Billing Log'!$K$2:$K$501) -> 0 | H14: =SUMPRODUCT(('Billing Log'!$H$2:$H$501<>"")*(MONTH('Billing Log'!$H$2:$H$501)=9)*('Billing Log'!$F$2:$F$501="NS06")*'Billing Log'!$I$2:$I$501) -> 0 | I14: =SUMPRODUCT(('Billing Log'!$J$2:$J$501<>"")*(MONTH('Billing Log'!$J$2:$J$501)=9)*('Billing Log'!$F$2:$F$501="NS06")*'Billing Log'!$K$2:$K$501) -> 0
A15: Oct | B15: =SUMPRODUCT(('Billing Log'!$H$2:$H$501<>"")*(MONTH('Billing Log'!$H$2:$H$501)=10)*(('Billing Log'!$F$2:$F$501="NS01")+('Billing Log'!$F$2:$F$501="NS02")+('Billing Log'!$F$2:$F$501="NS03"))*'Billing Log'!$I$2:$I$501) -> 0 | C15: =SUMPRODUCT(('Billing Log'!$J$2:$J$501<>"")*(MONTH('Billing Log'!$J$2:$J$501)=10)*(('Billing Log'!$F$2:$F$501="NS01")+('Billing Log'!$F$2:$F$501="NS02")+('Billing Log'!$F$2:$F$501="NS03"))*'Billing Log'!$K$2:$K$501) -> 0 | D15: =SUMPRODUCT(('Billing Log'!$H$2:$H$501<>"")*(MONTH('Billing Log'!$H$2:$H$501)=10)*('Billing Log'!$F$2:$F$501="NS04")*'Billing Log'!$I$2:$I$501) -> 0 | E15: =SUMPRODUCT(('Billing Log'!$J$2:$J$501<>"")*(MONTH('Billing Log'!$J$2:$J$501)=10)*('Billing Log'!$F$2:$F$501="NS04")*'Billing Log'!$K$2:$K$501) -> 0 | F15: =SUMPRODUCT(('Billing Log'!$H$2:$H$501<>"")*(MONTH('Billing Log'!$H$2:$H$501)=10)*('Billing Log'!$F$2:$F$501="NS05")*'Billing Log'!$I$2:$I$501) -> 192 | G15: =SUMPRODUCT(('Billing Log'!$J$2:$J$501<>"")*(MONTH('Billing Log'!$J$2:$J$501)=10)*('Billing Log'!$F$2:$F$501="NS05")*'Billing Log'!$K$2:$K$501) -> 0 | H15: =SUMPRODUCT(('Billing Log'!$H$2:$H$501<>"")*(MONTH('Billing Log'!$H$2:$H$501)=10)*('Billing Log'!$F$2:$F$501="NS06")*'Billing Log'!$I$2:$I$501) -> 0 | I15: =SUMPRODUCT(('Billing Log'!$J$2:$J$501<>"")*(MONTH('Billing Log'!$J$2:$J$501)=10)*('Billing Log'!$F$2:$F$501="NS06")*'Billing Log'!$K$2:$K$501) -> 0
A16: Nov | B16: =SUMPRODUCT(('Billing Log'!$H$2:$H$501<>"")*(MONTH('Billing Log'!$H$2:$H$501)=11)*(('Billing Log'!$F$2:$F$501="NS01")+('Billing Log'!$F$2:$F$501="NS02")+('Billing Log'!$F$2:$F$501="NS03"))*'Billing Log'!$I$2:$I$501) -> 0 | C16: =SUMPRODUCT(('Billing Log'!$J$2:$J$501<>"")*(MONTH('Billing Log'!$J$2:$J$501)=11)*(('Billing Log'!$F$2:$F$501="NS01")+('Billing Log'!$F$2:$F$501="NS02")+('Billing Log'!$F$2:$F$501="NS03"))*'Billing Log'!$K$2:$K$501) -> 0 | D16: =SUMPRODUCT(('Billing Log'!$H$2:$H$501<>"")*(MONTH('Billing Log'!$H$2:$H$501)=11)*('Billing Log'!$F$2:$F$501="NS04")*'Billing Log'!$I$2:$I$501) -> 0 | E16: =SUMPRODUCT(('Billing Log'!$J$2:$J$501<>"")*(MONTH('Billing Log'!$J$2:$J$501)=11)*('Billing Log'!$F$2:$F$501="NS04")*'Billing Log'!$K$2:$K$501) -> 0 | F16: =SUMPRODUCT(('Billing Log'!$H$2:$H$501<>"")*(MONTH('Billing Log'!$H$2:$H$501)=11)*('Billing Log'!$F$2:$F$501="NS05")*'Billing Log'!$I$2:$I$501) -> 192 | G16: =SUMPRODUCT(('Billing Log'!$J$2:$J$501<>"")*(MONTH('Billing Log'!$J$2:$J$501)=11)*('Billing Log'!$F$2:$F$501="NS05")*'Billing Log'!$K$2:$K$501) -> 192 | H16: =SUMPRODUCT(('Billing Log'!$H$2:$H$501<>"")*(MONTH('Billing Log'!$H$2:$H$501)=11)*('Billing Log'!$F$2:$F$501="NS06")*'Billing Log'!$I$2:$I$501) -> 0 | I16: =SUMPRODUCT(('Billing Log'!$J$2:$J$501<>"")*(MONTH('Billing Log'!$J$2:$J$501)=11)*('Billing Log'!$F$2:$F$501="NS06")*'Billing Log'!$K$2:$K$501) -> 0
A17: Dec | B17: =SUMPRODUCT(('Billing Log'!$H$2:$H$501<>"")*(MONTH('Billing Log'!$H$2:$H$501)=12)*(('Billing Log'!$F$2:$F$501="NS01")+('Billing Log'!$F$2:$F$501="NS02")+('Billing Log'!$F$2:$F$501="NS03"))*'Billing Log'!$I$2:$I$501) -> 0 | C17: =SUMPRODUCT(('Billing Log'!$J$2:$J$501<>"")*(MONTH('Billing Log'!$J$2:$J$501)=12)*(('Billing Log'!$F$2:$F$501="NS01")+('Billing Log'!$F$2:$F$501="NS02")+('Billing Log'!$F$2:$F$501="NS03"))*'Billing Log'!$K$2:$K$501) -> 0 | D17: =SUMPRODUCT(('Billing Log'!$H$2:$H$501<>"")*(MONTH('Billing Log'!$H$2:$H$501)=12)*('Billing Log'!$F$2:$F$501="NS04")*'Billing Log'!$I$2:$I$501) -> 0 | E17: =SUMPRODUCT(('Billing Log'!$J$2:$J$501<>"")*(MONTH('Billing Log'!$J$2:$J$501)=12)*('Billing Log'!$F$2:$F$501="NS04")*'Billing Log'!$K$2:$K$501) -> 0 | F17: =SUMPRODUCT(('Billing Log'!$H$2:$H$501<>"")*(MONTH('Billing Log'!$H$2:$H$501)=12)*('Billing Log'!$F$2:$F$501="NS05")*'Billing Log'!$I$2:$I$501) -> 192 | G17: =SUMPRODUCT(('Billing Log'!$J$2:$J$501<>"")*(MONTH('Billing Log'!$J$2:$J$501)=12)*('Billing Log'!$F$2:$F$501="NS05")*'Billing Log'!$K$2:$K$501) -> 192 | H17: =SUMPRODUCT(('Billing Log'!$H$2:$H$501<>"")*(MONTH('Billing Log'!$H$2:$H$501)=12)*('Billing Log'!$F$2:$F$501="NS06")*'Billing Log'!$I$2:$I$501) -> 0 | I17: =SUMPRODUCT(('Billing Log'!$J$2:$J$501<>"")*(MONTH('Billing Log'!$J$2:$J$501)=12)*('Billing Log'!$F$2:$F$501="NS06")*'Billing Log'!$K$2:$K$501) -> 0
A18: TOTAL | B18: =SUM(B6:B17) -> 5550 | C18: =SUM(C6:C17) -> 4350 | D18: =SUM(D6:D17) -> 1805 | E18: =SUM(E6:E17) -> 1330 | F18: =SUM(F6:F17) -> 5184 | G18: =SUM(G6:G17) -> 5184 | H18: =SUM(H6:H17) -> 935 | I18: =SUM(I6:I17) -> 850
A20: Note: Invoiced totals are bucketed by Invoice Date; Paid totals are bucketed by Date Paid. So a month's 'Invoiced' figure reflects what you billed that month, and 'Paid' reflects what actually came in that month, even if it relates to an invoice billed earlier.

Sheet Complex Cases
A1: Complex / Weird Cases Log
A2: Free-form log so you don't have to re-research a tricky case from scratch each time
A4: Patient Name | B4: Claim Number | C4: Date Logged | D4: What's Unusual | E4: Decision Made | F4: Decided By | G4: Date Decided | H4: Follow-up Needed | I4: Next Review Date | J4: Status | K4: Notes
A5: Terry Ah Chong | B5: 10052987765 | C5: 46183 | D5: NS04 approval granted while client still on visit 19 of NS03 package - approval window (10/06-10/07) may lapse before the 26th visit is reached, meaning approved units go unused and a fresh request is needed | E5: Flagged to ACC recovery team to confirm approach; continuing to monitor visit count weekly against approval end date | F5: S. Harrison (ACC Recovery Team) | G5: 46185 | H5: Yes | I5: 46208 | J5: Monitoring | K5: As of 01/07, client on visit 24. If 26th visit not reached by 10/07, new ACC179 required.
A6: Wiremu Delamere | B6: 10047765123 | C6: 45901 | D6: Client also receiving ACC-funded Home Help support concurrently with Ongoing Nursing | E6: Informed consent obtained from client, both services confirmed able to run concurrently | F6: Case Owner | G6: 45905 | H6: No | J6: Resolved
A7: Duc Minh Pham | B7: 10046654321 | C7: 46191 | D7: Sacral pressure injury developed secondary to original hip fracture immobility | E7: Consequential injury accepted, new ACC45 lodged for pressure injury, NS04 approval extended to include wound care | F7: Case Owner | G7: 46195 | H7: Yes | I7: 46218 | J7: Open | K7: Pressure injury staging documented, dressing regime under Extended Nursing
A8: Chevonne Ngata-Reid | B8: 10049988771 | C8: 46198 | D8: New shoulder injury from a fall, unrelated to original claim, sustained during a home visit | E8: New ACC45 lodged for Subsequent Injury; separate claim number pending from ACC | F8: Case Owner | G8: 46199 | H8: Yes | I8: 46223 | J8: Open | K8: Continue existing NS05 ongoing care under original claim while subsequent injury claim is processed
A9: Ashleigh Broughton | B9: 10054411002 | C9: 46162 | D9: Transferred from previous supplier mid-package; unclear how many NS03 consultations already used before transfer | E9: Requested clinical notes from previous supplier; ACC179 submitted for fresh NS04 approval pending confirmation of prior visit count | F9: Case Owner | G9: 46167 | H9: Yes | I9: 46211 | J9: Monitoring | K9: PO not yet issued - do not invoice until prior visit count confirmed

Sheet Decline Tracker
A1: Decline Letter Tracker
A2: Track declines from receipt through to resubmission outcome
A4: Patient Name | B4: Claim Number | C4: Decline Received Date | D4: Service/Period Declined | E4: Reason for Decline | F4: Date Nurse Emailed | G4: Date Resubmission Requested | H4: Outcome | I4: Date Outcome Received | J4: Status | K4: Notes
A5: Priya Naidu | B5: 10048811234 | C5: 46178 | D5: NS04 further extension (20 consults requested) | E5: Clinical notes insufficient to justify ongoing need beyond initial 25 consults | F5: 46179 | G5: 46193 | H5: Pending | J5: Awaiting response from ACC | K5: Updated wound photos and GP letter attached to resubmission
A6: Fa'amatuainu Petelo | B6: 10053322190 | C6: 46091 | D6: Comprehensive Nursing Assessment referral | E6: Referral form incomplete - missing referring GP details | F6: 46092 | G6: 46096 | H6: Overturned | I6: 46109 | J6: Accepted | K6: Resolved, assessment completed 02/04/26
A7: Sela Fifita | B7: 10050099887 | C7: 46154 | D7: NS06 treatments beyond 50-treatment cap (further 10 requested) | E7: Cap reached, insufficient justification provided for continued subsequent injury treatment | F7: 46155 | G7: 46172 | H7: Pending | J7: Awaiting nursing docs for resubmission | K7: GP asked to provide updated clinical justification before resubmission
A8: Rongomai Tapsell | B8: 10041122334 | C8: 46011 | D8: NS05 hours reduced from 4 to 2 hours p/month on renewal | E8: ACC clinical advisor assessed reduced need based on last Comprehensive Nursing Assessment | F8: 46013 | G8: 46027 | H8: Upheld | I8: 46032 | J8: Declined again | K8: Approval subsequently lapsed 10/01/26 - see NS04-NS05 Approvals tab, EXPIRED
